Workbook

Sheet 1st Shift Issue Sheet
B2: 1st Shift | O2: 1st Shift
B4: M/C No | C4: Issue Date | D4: Working Hour (Min) | E4: Buyer | F4: Style | G4: P.O | H4: Colour | I4: Size | J4: Production | K4: Lost Time (Min) | L4: Effective Time (Min) | M4: Remarks | O4: M/C No | P4: Issue Date | Q4: Working Hour (Min) | R4: Buyer | S4: Style | T4: P.O | U4: Colour | V4: Size | W4: Production | X4: Lost Time (Min) | Y4: Effective Time (Min) | Z4: Remarks | AF4: Today | AG4: Difference | AH4: Today | AI4: Difference
B5: 1 | D5: =12*60 -> 720 | L5: =IF(K5>0,D5-K5,720) -> 720 | O5: 101 | Q5: =12*60 -> 720 | Y5: =IF(X5>0,Q5-X5,720) -> 720 | AF5: =TODAY() -> 42479 | AG5: =IF(C5>0,AF5-C5,0) -> 0 | AH5: =TODAY() -> 42479 | AI5: =IF(P5>0,AH5-P5,0) -> 0
B6: 2 | D6: =12*60 -> 720 | L6: =IF(K6>0,D6-K6,720) -> 720 | O6: 102 | Q6: =12*60 -> 720 | Y6: =IF(X6>0,Q6-X6,720) -> 720 | AF6: =TODAY() -> 42479 | AG6: =IF(C6>0,AF6-C6,0) -> 0 | AH6: =TODAY() -> 42479 | AI6: =IF(P6>0,AH6-P6,0) -> 0
B7: 3 | D7: =12*60 -> 720 | L7: =IF(K7>0,D7-K7,720) -> 720 | O7: 103 | Q7: =12*60 -> 720 | Y7: =IF(X7>0,Q7-X7,720) -> 720 | AF7: =TODAY() -> 42479 | AG7: =IF(C7>0,AF7-C7,0) -> 0 | AH7: =TODAY() -> 42479 | AI7: =IF(P7>0,AH7-P7,0) -> 0
B8: 4 | D8: =12*60 -> 720 | L8: =IF(K8>0,D8-K8,720) -> 720 | O8: 104 | Q8: =12*60 -> 720 | Y8: =IF(X8>0,Q8-X8,720) -> 720 | AF8: =TODAY() -> 42479 | AG8: =IF(C8>0,AF8-C8,0) -> 0 | AH8: =TODAY() -> 42479 | AI8: =IF(P8>0,AH8-P8,0) -> 0
B9: 5 | D9: =12*60 -> 720 | L9: =IF(K9>0,D9-K9,720) -> 720 | O9: 105 | Q9: =12*60 -> 720 | Y9: =IF(X9>0,Q9-X9,720) -> 720 | AF9: =TODAY() -> 42479 | AG9: =IF(C9>0,AF9-C9,0) -> 0 | AH9: =TODAY() -> 42479 | AI9: =IF(P9>0,AH9-P9,0) -> 0
B10: 6 | D10: =12*60 -> 720 | L10: =IF(K10>0,D10-K10,720) -> 720 | O10: 106 | Q10: =12*60 -> 720 | Y10: =IF(X10>0,Q10-X10,720) -> 720 | AF10: =TODAY() -> 42479 | AG10: =IF(C10>0,AF10-C10,0) -> 0 | AH10: =TODAY() -> 42479 | AI10: =IF(P10>0,AH10-P10,0) -> 0
B11: 7 | D11: =12*60 -> 720 | L11: =IF(K11>0,D11-K11,720) -> 720 | O11: 107 | Q11: =12*60 -> 720 | Y11: =IF(X11>0,Q11-X11,720) -> 720 | AF11: =TODAY() -> 42479 | AG11: =IF(C11>0,AF11-C11,0) -> 0 | AH11: =TODAY() -> 42479 | AI11: =IF(P11>0,AH11-P11,0) -> 0
B12: 8 | D12: =12*60 -> 720 | L12: =IF(K12>0,D12-K12,720) -> 720 | O12: 108 | Q12: =12*60 -> 720 | Y12: =IF(X12>0,Q12-X12,720) -> 720 | AF12: =TODAY() -> 42479 | AG12: =IF(C12>0,AF12-C12,0) -> 0 | AH12: =TODAY() -> 42479 | AI12: =IF(P12>0,AH12-P12,0) -> 0
B13: 9 | D13: =12*60 -> 720 | L13: =IF(K13>0,D13-K13,720) -> 720 | O13: 109 | Q13: =12*60 -> 720 | Y13: =IF(X13>0,Q13-X13,720) -> 720 | AF13: =TODAY() -> 42479 | AG13: =IF(C13>0,AF13-C13,0) -> 0 | AH13: =TODAY() -> 42479 | AI13: =IF(P13>0,AH13-P13,0) -> 0
B14: 10 | D14: =12*60 -> 720 | L14: =IF(K14>0,D14-K14,720) -> 720 | O14: 110 | Q14: =12*60 -> 720 | Y14: =IF(X14>0,Q14-X14,720) -> 720 | AF14: =TODAY() -> 42479 | AG14: =IF(C14>0,AF14-C14,0) -> 0 | AH14: =TODAY() -> 42479 | AI14: =IF(P14>0,AH14-P14,0) -> 0
B15: 11 | D15: =12*60 -> 720 | L15: =IF(K15>0,D15-K15,720) -> 720 | O15: 111 | Q15: =12*60 -> 720 | Y15: =IF(X15>0,Q15-X15,720) -> 720 | AF15: =TODAY() -> 42479 | AG15: =IF(C15>0,AF15-C15,0) -> 0 | AH15: =TODAY() -> 42479 | AI15: =IF(P15>0,AH15-P15,0) -> 0
B16: 12 | D16: =12*60 -> 720 | L16: =IF(K16>0,D16-K16,720) -> 720 | O16: 112 | Q16: =12*60 -> 720 | Y16: =IF(X16>0,Q16-X16,720) -> 720 | AF16: =TODAY() -> 42479 | AG16: =IF(C16>0,AF16-C16,0) -> 0 | AH16: =TODAY() -> 42479 | AI16: =IF(P16>0,AH16-P16,0) -> 0
... B104: 100 | D104: =12*60 -> 720 | L104: =IF(K104>0,D104-K104,720) -> 720 | O104: 200 | Q104: =12*60 -> 720 | Y104: =IF(X104>0,Q104-X104,720) -> 720 | AF104: =TODAY() -> 42479 | AG104: =IF(C104>0,AF104-C104,0) -> 0 | AH104: =TODAY() -> 42479 | AI104: =IF(P104>0,AH104-P104,0) -> 0
B105: Total | J105: =SUM(J5:J104) -> 0 | K105: =SUM(K5:K104) -> 0 | L105: =SUM(L5:L104) -> 72000 | O105: Total | W105: =SUM(W5:W104) -> 0 | X105: =SUM(X5:X104) -> 0 | Y105: =SUM(Y5:Y104) -> 72000 | AF105: =TODAY() -> 42479 | AG105: =IF(C105>0,AF105-C105,0) -> 0 | AH105: =TODAY() -> 42479 | AI105: =IF(P105>0,AH105-P105,0) -> 0

Sheet 2nd Shift Issue Sheet
B2: 2nd Shift | O2: 2nd Shift
B4: M/C No | C4: Issue Date | D4: Working Hour (Min) | E4: Buyer | F4: Style | G4: P.O | H4: Colour | I4: Size | J4: Production | K4: Lost Time (Min) | L4: Effective Time (Min) | M4: Remarks | O4: M/C No | P4: Issue Date | Q4: Working Hour (Min) | R4: Buyer | S4: Style | T4: P.O | U4: Colour | V4: Size | W4: Production | X4: Lost Time (Min) | Y4: Effective Time (Min) | Z4: Remarks | AF4: Today | AG4: Difference | AH4: Today | AI4: Difference
B5: 1 | D5: =12*60 -> 720 | L5: =IF(K5>0,D5-K5,720) -> 720 | O5: 101 | Q5: =12*60 -> 720 | Y5: =IF(X5>0,Q5-X5,720) -> 720 | AF5: =TODAY() -> 42479 | AG5: =IF(C5>0,AF5-C5,0) -> 0 | AH5: =TODAY() -> 42479 | AI5: =IF(P5>0,AH5-P5,0) -> 0
B6: 2 | D6: =12*60 -> 720 | L6: =IF(K6>0,D6-K6,720) -> 720 | O6: 102 | Q6: =12*60 -> 720 | Y6: =IF(X6>0,Q6-X6,720) -> 720 | AF6: =TODAY() -> 42479 | AG6: =IF(C6>0,AF6-C6,0) -> 0 | AH6: =TODAY() -> 42479 | AI6: =IF(P6>0,AH6-P6,0) -> 0
B7: 3 | D7: =12*60 -> 720 | L7: =IF(K7>0,D7-K7,720) -> 720 | O7: 103 | Q7: =12*60 -> 720 | Y7: =IF(X7>0,Q7-X7,720) -> 720 | AF7: =TODAY() -> 42479 | AG7: =IF(C7>0,AF7-C7,0) -> 0 | AH7: =TODAY() -> 42479 | AI7: =IF(P7>0,AH7-P7,0) -> 0
B8: 4 | D8: =12*60 -> 720 | L8: =IF(K8>0,D8-K8,720) -> 720 | O8: 104 | Q8: =12*60 -> 720 | Y8: =IF(X8>0,Q8-X8,720) -> 720 | AF8: =TODAY() -> 42479 | AG8: =IF(C8>0,AF8-C8,0) -> 0 | AH8: =TODAY() -> 42479 | AI8: =IF(P8>0,AH8-P8,0) -> 0
B9: 5 | D9: =12*60 -> 720 | L9: =IF(K9>0,D9-K9,720) -> 720 | O9: 105 | Q9: =12*60 -> 720 | Y9: =IF(X9>0,Q9-X9,720) -> 720 | AF9: =TODAY() -> 42479 | AG9: =IF(C9>0,AF9-C9,0) -> 0 | AH9: =TODAY() -> 42479 | AI9: =IF(P9>0,AH9-P9,0) -> 0
B10: 6 | D10: =12*60 -> 720 | L10: =IF(K10>0,D10-K10,720) -> 720 | O10: 106 | Q10: =12*60 -> 720 | Y10: =IF(X10>0,Q10-X10,720) -> 720 | AF10: =TODAY() -> 42479 | AG10: =IF(C10>0,AF10-C10,0) -> 0 | AH10: =TODAY() -> 42479 | AI10: =IF(P10>0,AH10-P10,0) -> 0
B11: 7 | D11: =12*60 -> 720 | L11: =IF(K11>0,D11-K11,720) -> 720 | O11: 107 | Q11: =12*60 -> 720 | Y11: =IF(X11>0,Q11-X11,720) -> 720 | AF11: =TODAY() -> 42479 | AG11: =IF(C11>0,AF11-C11,0) -> 0 | AH11: =TODAY() -> 42479 | AI11: =IF(P11>0,AH11-P11,0) -> 0
B12: 8 | D12: =12*60 -> 720 | L12: =IF(K12>0,D12-K12,720) -> 720 | O12: 108 | Q12: =12*60 -> 720 | Y12: =IF(X12>0,Q12-X12,720) -> 720 | AF12: =TODAY() -> 42479 | AG12: =IF(C12>0,AF12-C12,0) -> 0 | AH12: =TODAY() -> 42479 | AI12: =IF(P12>0,AH12-P12,0) -> 0
B13: 9 | D13: =12*60 -> 720 | L13: =IF(K13>0,D13-K13,720) -> 720 | O13: 109 | Q13: =12*60 -> 720 | Y13: =IF(X13>0,Q13-X13,720) -> 720 | AF13: =TODAY() -> 42479 | AG13: =IF(C13>0,AF13-C13,0) -> 0 | AH13: =TODAY() -> 42479 | AI13: =IF(P13>0,AH13-P13,0) -> 0
B14: 10 | D14: =12*60 -> 720 | L14: =IF(K14>0,D14-K14,720) -> 720 | O14: 110 | Q14: =12*60 -> 720 | Y14: =IF(X14>0,Q14-X14,720) -> 720 | AF14: =TODAY() -> 42479 | AG14: =IF(C14>0,AF14-C14,0) -> 0 | AH14: =TODAY() -> 42479 | AI14: =IF(P14>0,AH14-P14,0) -> 0
B15: 11 | D15: =12*60 -> 720 | L15: =IF(K15>0,D15-K15,720) -> 720 | O15: 111 | Q15: =12*60 -> 720 | Y15: =IF(X15>0,Q15-X15,720) -> 720 | AF15: =TODAY() -> 42479 | AG15: =IF(C15>0,AF15-C15,0) -> 0 | AH15: =TODAY() -> 42479 | AI15: =IF(P15>0,AH15-P15,0) -> 0
B16: 12 | D16: =12*60 -> 720 | L16: =IF(K16>0,D16-K16,720) -> 720 | O16: 112 | Q16: =12*60 -> 720 | Y16: =IF(X16>0,Q16-X16,720) -> 720 | AF16: =TODAY() -> 42479 | AG16: =IF(C16>0,AF16-C16,0) -> 0 | AH16: =TODAY() -> 42479 | AI16: =IF(P16>0,AH16-P16,0) -> 0
... B104: 100 | D104: =12*60 -> 720 | L104: =IF(K104>0,D104-K104,720) -> 720 | O104: 200 | Q104: =12*60 -> 720 | Y104: =IF(X104>0,Q104-X104,720) -> 720 | AF104: =TODAY() -> 42479 | AG104: =IF(C104>0,AF104-C104,0) -> 0 | AH104: =TODAY() -> 42479 | AI104: =IF(P104>0,AH104-P104,0) -> 0
B105: Total | J105: =SUM(J5:J104) -> 0 | K105: =SUM(K5:K104) -> 0 | L105: =SUM(L5:L104) -> 72000 | O105: Total | W105: =SUM(W5:W104) -> 0 | X105: =SUM(X5:X104) -> 0 | Y105: =SUM(Y5:Y104) -> 72000 | AF105: =TODAY() -> 42479 | AG105: =IF(C105>0,AF105-C105,0) -> 0 | AH105: =TODAY() -> 42479 | AI105: =IF(P105>0,AH105-P105,0) -> 0

Sheet (1st+2nd) Shift Combined
C5: Style Wise Running M/C (1st Shift) | M5: Style Wise Running M/C (2nd Shift)
C7: Total (Left Side-1st Shift) | H7: Total (Right Side-1st Shift) | M7: Total (Left Side-2nd Shift) | R7: Total (Right Side-2nd Shift)
C8: Buyer | D8: Style | E8: M/C | F8: Pcs Qty | H8: Buyer | I8: Style | J8: M/C | K8: Pcs Qty | M8: Buyer | N8: Style | O8: M/C | P8: Pcs Qty | R8: Buyer | S8: Style | T8: M/C | U8: Pcs Qty
C9: Kiabi | D9: 16Gesfi | E9: =COUNTIF('1st Shift Issue Sheet'!F5:F104,"16Gesfi") -> 0 | F9: =SUMIF('1st Shift Issue Sheet'!F5:F104,"16Gesfi",'1st Shift Issue Sheet'!J5:J104) -> 0 | H9: Kiabi | I9: 16Gesfi | J9: =COUNTIF('1st Shift Issue Sheet'!S5:S104,"16Gesfi") -> 0 | K9: =SUMIF('1st Shift Issue Sheet'!S5:S104,"16Gesfi",'1st Shift Issue Sheet'!W5:W104) -> 0 | M9: Kiabi | N9: 16Gesfi | O9: =COUNTIF('1st Shift Issue Sheet'!F5:F104,"16Gesfi") -> 0 | P9: =SUMIF('1st Shift Issue Sheet'!F5:F104,"16Gesfi",'1st Shift Issue Sheet'!J5:J104) -> 0 | R9: Kiabi | S9: 16Gesfi | T9: =COUNTIF('1st Shift Issue Sheet'!S5:S104,"16Gesfi") -> 0 | U9: =SUMIF('1st Shift Issue Sheet'!S5:S104,"16Gesfi",'1st Shift Issue Sheet'!W5:W104) -> 0
C10: Kiabi | D10: Gpans | E10: =COUNTIF('1st Shift Issue Sheet'!F5:F104,"Gpans") -> 0 | F10: =SUMIF('1st Shift Issue Sheet'!F5:F104,"Gpans",'1st Shift Issue Sheet'!J5:J104) -> 0 | H10: Kiabi | I10: Gpans | J10: =COUNTIF('1st Shift Issue Sheet'!S5:S104,"Gpans") -> 0 | K10: =SUMIF('1st Shift Issue Sheet'!S5:S104,"Gpans",'1st Shift Issue Sheet'!W5:W104) -> 0 | M10: Kiabi | N10: Gpans | O10: =COUNTIF('1st Shift Issue Sheet'!F5:F104,"Gpans") -> 0 | P10: =SUMIF('1st Shift Issue Sheet'!F5:F104,"Gpans",'1st Shift Issue Sheet'!J5:J104) -> 0 | R10: Kiabi | S10: Gpans | T10: =COUNTIF('1st Shift Issue Sheet'!S5:S104,"Gpans") -> 0 | U10: =SUMIF('1st Shift Issue Sheet'!S5:S104,"Gpans",'1st Shift Issue Sheet'!W5:W104) -> 0
C22: Grand Total | E22: =IF(SUM(E9:E21)>0,SUM(E9:E21),0) -> 0 | F22: =IF(SUM(F9:F21)>0,SUM(F9:F21),0) -> 0 | H22: Grand Total | J22: =IF(SUM(J9:J21)>0,SUM(J9:J21),0) -> 0 | K22: =IF(SUM(K9:K21)>0,SUM(K9:K21),0) -> 0 | M22: Grand Total | O22: =IF(SUM(O9:O21)>0,SUM(O9:O21),0) -> 0 | P22: =IF(SUM(P9:P21)>0,SUM(P9:P21),0) -> 0 | R22: Grand Total | T22: =IF(SUM(T9:T21)>0,SUM(T9:T21),0) -> 0 | U22: =IF(SUM(U9:U21)>0,SUM(U9:U21),0) -> 0
B29: M/C | C29: Qty | D29: Status | F29: Count | G29: Cmmnts | I29: M/C | J29: Qty | K29: Status | M29: Count | N29: Cmmnts
B30: 1 | C30: ='1st Shift Issue Sheet'!J5 -> 0 | D30: =IF('1st Shift Issue Sheet'!J5>0,"Running","Not Running") -> Not Running | F30: =COUNT('1st Shift Issue Sheet'!D5) -> 1 | G30: =IF('1st Shift Issue Sheet'!AG5>=2,"Alarm","") | I30: 101 | J30: ='1st Shift Issue Sheet'!W5 -> 0 | K30: =IF('1st Shift Issue Sheet'!W5>0,"Running","Not Running") -> Not Running | M30: =COUNT('1st Shift Issue Sheet'!Q5) -> 1 | N30: =IF('1st Shift Issue Sheet'!AI5>=2,"Alarm","")
B31: 2 | C31: ='1st Shift Issue Sheet'!J6 -> 0 | D31: =IF('1st Shift Issue Sheet'!J6>0,"Running","Not Running") -> Not Running | F31: =COUNT('1st Shift Issue Sheet'!D6) -> 1 | G31: =IF('1st Shift Issue Sheet'!AG6>=2,"Alarm","") | I31: 102 | J31: ='1st Shift Issue Sheet'!W6 -> 0 | K31: =IF('1st Shift Issue Sheet'!W6>0,"Running","Not Running") -> Not Running | M31: =COUNT('1st Shift Issue Sheet'!Q6) -> 1 | N31: =IF('1st Shift Issue Sheet'!AI6>=2,"Alarm","")
B32: 3 | C32: ='1st Shift Issue Sheet'!J7 -> 0 | D32: =IF('1st Shift Issue Sheet'!J7>0,"Running","Not Running") -> Not Running | F32: =COUNT('1st Shift Issue Sheet'!D7) -> 1 | G32: =IF('1st Shift Issue Sheet'!AG7>=2,"Alarm","") | I32: 103 | J32: ='1st Shift Issue Sheet'!W7 -> 0 | K32: =IF('1st Shift Issue Sheet'!W7>0,"Running","Not Running") -> Not Running | M32: =COUNT('1st Shift Issue Sheet'!Q7) -> 1 | N32: =IF('1st Shift Issue Sheet'!AI7>=2,"Alarm","")
B33: 4 | C33: ='1st Shift Issue Sheet'!J8 -> 0 | D33: =IF('1st Shift Issue Sheet'!J8>0,"Running","Not Running") -> Not Running | F33: =COUNT('1st Shift Issue Sheet'!D8) -> 1 | G33: =IF('1st Shift Issue Sheet'!AG8>=2,"Alarm","") | I33: 104 | J33: ='1st Shift Issue Sheet'!W8 -> 0 | K33: =IF('1st Shift Issue Sheet'!W8>0,"Running","Not Running") -> Not Running | M33: =COUNT('1st Shift Issue Sheet'!Q8) -> 1 | N33: =IF('1st Shift Issue Sheet'!AI8>=2,"Alarm","")
B34: 5 | C34: ='1st Shift Issue Sheet'!J9 -> 0 | D34: =IF('1st Shift Issue Sheet'!J9>0,"Running","Not Running") -> Not Running | F34: =COUNT('1st Shift Issue Sheet'!D9) -> 1 | G34: =IF('1st Shift Issue Sheet'!AG9>=2,"Alarm","") | I34: 105 | J34: ='1st Shift Issue Sheet'!W9 -> 0 | K34: =IF('1st Shift Issue Sheet'!W9>0,"Running","Not Running") -> Not Running | M34: =COUNT('1st Shift Issue Sheet'!Q9) -> 1 | N34: =IF('1st Shift Issue Sheet'!AI9>=2,"Alarm","")
B35: 6 | C35: ='1st Shift Issue Sheet'!J10 -> 0 | D35: =IF('1st Shift Issue Sheet'!J10>0,"Running","Not Running") -> Not Running | F35: =COUNT('1st Shift Issue Sheet'!D10) -> 1 | G35: =IF('1st Shift Issue Sheet'!AG10>=2,"Alarm","") | I35: 106 | J35: ='1st Shift Issue Sheet'!W10 -> 0 | K35: =IF('1st Shift Issue Sheet'!W10>0,"Running","Not Running") -> Not Running | M35: =COUNT('1st Shift Issue Sheet'!Q10) -> 1 | N35: =IF('1st Shift Issue Sheet'!AI10>=2,"Alarm","")
B36: 7 | C36: ='1st Shift Issue Sheet'!J11 -> 0 | D36: =IF('1st Shift Issue Sheet'!J11>0,"Running","Not Running") -> Not Running | F36: =COUNT('1st Shift Issue Sheet'!D11) -> 1 | G36: =IF('1st Shift Issue Sheet'!AG11>=2,"Alarm","") | I36: 107 | J36: ='1st Shift Issue Sheet'!W11 -> 0 | K36: =IF('1st Shift Issue Sheet'!W11>0,"Running","Not Running") -> Not Running | M36: =COUNT('1st Shift Issue Sheet'!Q11) -> 1 | N36: =IF('1st Shift Issue Sheet'!AI11>=2,"Alarm","")
B37: 8 | C37: ='1st Shift Issue Sheet'!J12 -> 0 | D37: =IF('1st Shift Issue Sheet'!J12>0,"Running","Not Running") -> Not Running | F37: =COUNT('1st Shift Issue Sheet'!D12) -> 1 | G37: =IF('1st Shift Issue Sheet'!AG12>=2,"Alarm","") | I37: 108 | J37: ='1st Shift Issue Sheet'!W12 -> 0 | K37: =IF('1st Shift Issue Sheet'!W12>0,"Running","Not Running") -> Not Running | M37: =COUNT('1st Shift Issue Sheet'!Q12) -> 1 | N37: =IF('1st Shift Issue Sheet'!AI12>=2,"Alarm","")
B38: 9 | C38: ='1st Shift Issue Sheet'!J13 -> 0 | D38: =IF('1st Shift Issue Sheet'!J13>0,"Running","Not Running") -> Not Running | F38: =COUNT('1st Shift Issue Sheet'!D13) -> 1 | G38: =IF('1st Shift Issue Sheet'!AG13>=2,"Alarm","") | I38: 109 | J38: ='1st Shift Issue Sheet'!W13 -> 0 | K38: =IF('1st Shift Issue Sheet'!W13>0,"Running","Not Running") -> Not Running | M38: =COUNT('1st Shift Issue Sheet'!Q13) -> 1 | N38: =IF('1st Shift Issue Sheet'!AI13>=2,"Alarm","")
B39: 10 | C39: ='1st Shift Issue Sheet'!J14 -> 0 | D39: =IF('1st Shift Issue Sheet'!J14>0,"Running","Not Running") -> Not Running | F39: =COUNT('1st Shift Issue Sheet'!D14) -> 1 | G39: =IF('1st Shift Issue Sheet'!AG14>=2,"Alarm","") | I39: 110 | J39: ='1st Shift Issue Sheet'!W14 -> 0 | K39: =IF('1st Shift Issue Sheet'!W14>0,"Running","Not Running") -> Not Running | M39: =COUNT('1st Shift Issue Sheet'!Q14) -> 1 | N39: =IF('1st Shift Issue Sheet'!AI14>=2,"Alarm","")
B40: 11 | C40: ='1st Shift Issue Sheet'!J15 -> 0 | D40: =IF('1st Shift Issue Sheet'!J15>0,"Running","Not Running") -> Not Running | F40: =COUNT('1st Shift Issue Sheet'!D15) -> 1 | G40: =IF('1st Shift Issue Sheet'!AG15>=2,"Alarm","") | I40: 111 | J40: ='1st Shift Issue Sheet'!W15 -> 0 | K40: =IF('1st Shift Issue Sheet'!W15>0,"Running","Not Running") -> Not Running | M40: =COUNT('1st Shift Issue Sheet'!Q15) -> 1 | N40: =IF('1st Shift Issue Sheet'!AI15>=2,"Alarm","")
B41: 12 | C41: ='1st Shift Issue Sheet'!J16 -> 0 | D41: =IF('1st Shift Issue Sheet'!J16>0,"Running","Not Running") -> Not Running | F41: =COUNT('1st Shift Issue Sheet'!D16) -> 1 | G41: =IF('1st Shift Issue Sheet'!AG16>=2,"Alarm","") | I41: 112 | J41: ='1st Shift Issue Sheet'!W16 -> 0 | K41: =IF('1st Shift Issue Sheet'!W16>0,"Running","Not Running") -> Not Running | M41: =COUNT('1st Shift Issue Sheet'!Q16) -> 1 | N41: =IF('1st Shift Issue Sheet'!AI16>=2,"Alarm","")
... B129: 100 | C129: ='1st Shift Issue Sheet'!J104 -> 0 | D129: =IF('1st Shift Issue Sheet'!J104>0,"Running","Not Running") -> Not Running | F129: =COUNT('1st Shift Issue Sheet'!D104) -> 1 | G129: =IF('1st Shift Issue Sheet'!AG104>=2,"Alarm","") | I129: 200 | J129: ='1st Shift Issue Sheet'!W104 -> 0 | K129: =IF('1st Shift Issue Sheet'!W104>0,"Running","Not Running") -> Not Running | M129: =COUNT('1st Shift Issue Sheet'!Q104) -> 1 | N129: =IF('1st Shift Issue Sheet'!AI104>=2,"Alarm","")

Sheet Summery Sheet
D4: Style Wise Running M/C
D6: Total
D7: Buyer | E7: Style | F7: M/C | G7: Pcs Qty
D8: Kiabi | E8: Gesfi | F8: ='(1st+2nd) Shift Combined'!E9+'(1st+2nd) Shift Combined'!J9+'(1st+2nd) Shift Combined'!O9+'(1st+2nd) Shift Combined'!T9 -> 0 | G8: ='(1st+2nd) Shift Combined'!F9+'(1st+2nd) Shift Combined'!K9+'(1st+2nd) Shift Combined'!P9+'(1st+2nd) Shift Combined'!U9 -> 0
D9: Kiabi | E9: Gpans | F9: ='(1st+2nd) Shift Combined'!E10+'(1st+2nd) Shift Combined'!J10+'(1st+2nd) Shift Combined'!O10+'(1st+2nd) Shift Combined'!T10 -> 0 | G9: ='(1st+2nd) Shift Combined'!F10+'(1st+2nd) Shift Combined'!K10+'(1st+2nd) Shift Combined'!P10+'(1st+2nd) Shift Combined'!U10 -> 0
I11: Total M/C | K11: =200 -> 200
I12: Total Working Hour (Min) | K12: =72000*4 -> 288000
I13: Total Production | K13: ='1st Shift Issue Sheet'!J105+'2nd Shift Issue Sheet'!J105+'1st Shift Issue Sheet'!W105+'2nd Shift Issue Sheet'!W105 -> 0
I14: Total Lost Time (Min) | K14: ='1st Shift Issue Sheet'!K105+'2nd Shift Issue Sheet'!K105+'1st Shift Issue Sheet'!X105+'2nd Shift Issue Sheet'!X105 -> 0
I15: Total Effective Time (Min) | K15: ='1st Shift Issue Sheet'!L105+'1st Shift Issue Sheet'!Y105+'2nd Shift Issue Sheet'!L105+'2nd Shift Issue Sheet'!Y105 -> 288000
D21: Grand Total | F21: =IF(SUM(F8:F20)>0,SUM(F8:F20),0) -> 0 | G21: =IF(SUM(G8:G20)>0,SUM(G8:G20),0) -> 0

Sheet MC Layout
AB2: PATH
D5: M/C No-01 | I5: M/C No-02 | N5: M/C No-03 | S5: M/C No-04 | X5: M/C No-05 | AI5: M/C No-101 | AN5: M/C No-102 | AS5: M/C No-103 | AX5: M/C No-104 | BC5: M/C No-105
C6: ='(1st+2nd) Shift Combined'!D30 -> Not Running | H6: ='(1st+2nd) Shift Combined'!D31 -> Not Running | M6: ='(1st+2nd) Shift Combined'!D32 -> Not Running | R6: ='(1st+2nd) Shift Combined'!D33 -> Not Running | W6: ='(1st+2nd) Shift Combined'!D34 -> Not Running | AH6: ='(1st+2nd) Shift Combined'!K30 -> Not Running | AM6: ='(1st+2nd) Shift Combined'!K31 -> Not Running | AR6: ='(1st+2nd) Shift Combined'!K32 -> Not Running | AW6: ='(1st+2nd) Shift Combined'!K33 -> Not Running | BB6: ='(1st+2nd) Shift Combined'!K34 -> Not Running
D9: ='(1st+2nd) Shift Combined'!G30 | I9: ='(1st+2nd) Shift Combined'!G31 | N9: ='(1st+2nd) Shift Combined'!G32 | S9: ='(1st+2nd) Shift Combined'!G33 | X9: ='(1st+2nd) Shift Combined'!G34 | AI9: ='(1st+2nd) Shift Combined'!N30 | AN9: ='(1st+2nd) Shift Combined'!N31 | AS9: ='(1st+2nd) Shift Combined'!N32 | AX9: ='(1st+2nd) Shift Combined'!N33 | BC9: ='(1st+2nd) Shift Combined'!N34
D11: M/C No-06 | I11: M/C No-07 | N11: M/C No-08 | S11: M/C No-09 | X11: M/C No-10 | AI11: M/C No-106 | AN11: M/C No-107 | AS11: M/C No-108 | AX11: M/C No-109 | BC11: M/C No-110
C12: ='(1st+2nd) Shift Combined'!D35 -> Not Running | H12: ='(1st+2nd) Shift Combined'!D36 -> Not Running | M12: ='(1st+2nd) Shift Combined'!D37 -> Not Running | R12: ='(1st+2nd) Shift Combined'!D38 -> Not Running | W12: ='(1st+2nd) Shift Combined'!D39 -> Not Running | AH12: ='(1st+2nd) Shift Combined'!K35 -> Not Running | AM12: ='(1st+2nd) Shift Combined'!K36 -> Not Running | AR12: ='(1st+2nd) Shift Combined'!K37 -> Not Running | AW12: ='(1st+2nd) Shift Combined'!K38 -> Not Running | BB12: ='(1st+2nd) Shift Combined'!K39 -> Not Running
D15: ='(1st+2nd) Shift Combined'!G35 | I15: ='(1st+2nd) Shift Combined'!G36 | N15: ='(1st+2nd) Shift Combined'!G37 | S15: ='(1st+2nd) Shift Combined'!G38 | X15: ='(1st+2nd) Shift Combined'!G39 | AI15: ='(1st+2nd) Shift Combined'!N35 | AN15: ='(1st+2nd) Shift Combined'!N36 | AS15: ='(1st+2nd) Shift Combined'!N37 | AX15: ='(1st+2nd) Shift Combined'!N38 | BC15: ='(1st+2nd) Shift Combined'!N39
D17: M/C No-11 | I17: M/C No-12 | N17: M/C No-13 | S17: M/C No-14 | X17: M/C No-15 | AI17: M/C No-111 | AN17: M/C No-112 | AS17: M/C No-113 | AX17: M/C No-14 | BC17: M/C No-115
C18: ='(1st+2nd) Shift Combined'!D40 -> Not Running | H18: ='(1st+2nd) Shift Combined'!D41 -> Not Running | M18: ='(1st+2nd) Shift Combined'!D42 -> Not Running | R18: ='(1st+2nd) Shift Combined'!D43 -> Not Running | W18: ='(1st+2nd) Shift Combined'!D44 -> Not Running | AH18: ='(1st+2nd) Shift Combined'!K40 -> Not Running | AM18: ='(1st+2nd) Shift Combined'!K41 -> Not Running | AR18: ='(1st+2nd) Shift Combined'!K42 -> Not Running | AW18: ='(1st+2nd) Shift Combined'!K43 -> Not Running | BB18: ='(1st+2nd) Shift Combined'!K44 -> Not Running
D21: ='(1st+2nd) Shift Combined'!G40 | I21: ='(1st+2nd) Shift Combined'!G41 | N21: ='(1st+2nd) Shift Combined'!G42 | S21: ='(1st+2nd) Shift Combined'!G43 | X21: ='(1st+2nd) Shift Combined'!G44 | AI21: ='(1st+2nd) Shift Combined'!N40 | AN21: ='(1st+2nd) Shift Combined'!N41 | AS21: ='(1st+2nd) Shift Combined'!N42 | AX21: ='(1st+2nd) Shift Combined'!N43 | BC21: ='(1st+2nd) Shift Combined'!N44
D23: M/C No-16 | I23: M/C No-17 | N23: M/C No-18 | S23: M/C No-19 | X23: M/C No-20 | AI23: M/C No-116 | AN23: M/C No-17 | AS23: M/C No-18 | AX23: M/C No-19 | BC23: M/C No-120
C24: ='(1st+2nd) Shift Combined'!D45 -> Not Running | H24: ='(1st+2nd) Shift Combined'!D46 -> Not Running | M24: ='(1st+2nd) Shift Combined'!D47 -> Not Running | R24: ='(1st+2nd) Shift Combined'!D48 -> Not Running | W24: ='(1st+2nd) Shift Combined'!D49 -> Not Running | AH24: ='(1st+2nd) Shift Combined'!K45 -> Not Running | AM24: ='(1st+2nd) Shift Combined'!K46 -> Not Running | AR24: ='(1st+2nd) Shift Combined'!K47 -> Not Running | AW24: ='(1st+2nd) Shift Combined'!K48 -> Not Running | BB24: ='(1st+2nd) Shift Combined'!K49 -> Not Running
D27: ='(1st+2nd) Shift Combined'!G45 | I27: ='(1st+2nd) Shift Combined'!G46 | N27: ='(1st+2nd) Shift Combined'!G47 | S27: ='(1st+2nd) Shift Combined'!G48 | X27: ='(1st+2nd) Shift Combined'!G49 | AI27: ='(1st+2nd) Shift Combined'!N45 | AN27: ='(1st+2nd) Shift Combined'!N46 | AS27: ='(1st+2nd) Shift Combined'!N47 | AX27: ='(1st+2nd) Shift Combined'!N48 | BC27: ='(1st+2nd) Shift Combined'!N49
D29: M/C No-21 | I29: M/C No-22 | N29: M/C No-23 | S29: M/C No-24 | X29: M/C No-25 | AI29: M/C No-121 | AN29: M/C No-22 | AS29: M/C No-23 | AX29: M/C No-24 | BC29: M/C No-125
C30: ='(1st+2nd) Shift Combined'!D50 -> Not Running | H30: ='(1st+2nd) Shift Combined'!D51 -> Not Running | M30: ='(1st+2nd) Shift Combined'!D52 -> Not Running | R30: ='(1st+2nd) Shift Combined'!D53 -> Not Running | W30: ='(1st+2nd) Shift Combined'!D54 -> Not Running | AH30: ='(1st+2nd) Shift Combined'!K50 -> Not Running | AM30: ='(1st+2nd) Shift Combined'!K51 -> Not Running | AR30: ='(1st+2nd) Shift Combined'!K52 -> Not Running | AW30: ='(1st+2nd) Shift Combined'!K53 -> Not Running | BB30: ='(1st+2nd) Shift Combined'!K54 -> Not Running
D33: ='(1st+2nd) Shift Combined'!G50 | I33: ='(1st+2nd) Shift Combined'!G51 | N33: ='(1st+2nd) Shift Combined'!G52 | S33: ='(1st+2nd) Shift Combined'!G53 | X33: ='(1st+2nd) Shift Combined'!G54 | AI33: ='(1st+2nd) Shift Combined'!N50 | AN33: ='(1st+2nd) Shift Combined'!N51 | AS33: ='(1st+2nd) Shift Combined'!N52 | AX33: ='(1st+2nd) Shift Combined'!N53 | BC33: ='(1st+2nd) Shift Combined'!N54
D35: M/C No-26 | I35: M/C No-27 | N35: M/C No-28 | S35: M/C No-29 | X35: M/C No-30 | AI35: M/C No-126 | AN35: M/C No-127 | AS35: M/C No-128 | AX35: M/C No-219 | BC35: M/C No-130
C36: ='(1st+2nd) Shift Combined'!D55 -> Not Running | H36: ='(1st+2nd) Shift Combined'!D56 -> Not Running | M36: ='(1st+2nd) Shift Combined'!D57 -> Not Running | R36: ='(1st+2nd) Shift Combined'!D58 -> Not Running | W36: ='(1st+2nd) Shift Combined'!D59 -> Not Running | AH36: ='(1st+2nd) Shift Combined'!K55 -> Not Running | AM36: ='(1st+2nd) Shift Combined'!K56 -> Not Running | AR36: ='(1st+2nd) Shift Combined'!K57 -> Not Running | AW36: ='(1st+2nd) Shift Combined'!K58 -> Not Running | BB36: ='(1st+2nd) Shift Combined'!K59 -> Not Running
D39: ='(1st+2nd) Shift Combined'!G55 | I39: ='(1st+2nd) Shift Combined'!G56 | N39: ='(1st+2nd) Shift Combined'!G57 | S39: ='(1st+2nd) Shift Combined'!G58 | X39: ='(1st+2nd) Shift Combined'!G59 | AI39: ='(1st+2nd) Shift Combined'!N55 | AN39: ='(1st+2nd) Shift Combined'!N56 | AS39: ='(1st+2nd) Shift Combined'!N57 | AX39: ='(1st+2nd) Shift Combined'!N58 | BC39: ='(1st+2nd) Shift Combined'!N59
B40: PATH | AG40: PATH
AB48: PATH
D49: M/C No-31 | I49: M/C No-32 | N49: M/C No-33 | S49: M/C No-34 | X49: M/C No-35 | AI49: M/C No-131 | AN49: M/C No-132 | AS49: M/C No-133 | AX49: M/C No-134 | BC49: M/C No-135
C50: ='(1st+2nd) Shift Combined'!D60 -> Not Running | H50: ='(1st+2nd) Shift Combined'!D61 -> Not Running | M50: ='(1st+2nd) Shift Combined'!D62 -> Not Running | R50: ='(1st+2nd) Shift Combined'!D63 -> Not Running | W50: ='(1st+2nd) Shift Combined'!D64 -> Not Running | AH50: ='(1st+2nd) Shift Combined'!K60 -> Not Running | AM50: ='(1st+2nd) Shift Combined'!K61 -> Not Running | AR50: ='(1st+2nd) Shift Combined'!K62 -> Not Running | AW50: ='(1st+2nd) Shift Combined'!K63 -> Not Running | BB50: ='(1st+2nd) Shift Combined'!K64 -> Not Running
D53: ='(1st+2nd) Shift Combined'!G60 | I53: ='(1st+2nd) Shift Combined'!G61 | N53: ='(1st+2nd) Shift Combined'!G62 | S53: ='(1st+2nd) Shift Combined'!G63 | X53: ='(1st+2nd) Shift Combined'!G64 | AI53: ='(1st+2nd) Shift Combined'!N60 | AN53: ='(1st+2nd) Shift Combined'!N61 | AS53: ='(1st+2nd) Shift Combined'!N62 | AX53: ='(1st+2nd) Shift Combined'!N63 | BC53: ='(1st+2nd) Shift Combined'!N64
D55: M/C No-36 | I55: M/C No-37 | N55: M/C No-38 | S55: M/C No-39 | X55: M/C No-40 | AI55: M/C No-136 | AN55: M/C No-137 | AS55: M/C No-138 | AX55: M/C No-139 | BC55: M/C No-140
C56: ='(1st+2nd) Shift Combined'!D65 -> Not Running | H56: ='(1st+2nd) Shift Combined'!D66 -> Not Running | M56: ='(1st+2nd) Shift Combined'!D67 -> Not Running | R56: ='(1st+2nd) Shift Combined'!D68 -> Not Running | W56: ='(1st+2nd) Shift Combined'!D69 -> Not Running | AH56: ='(1st+2nd) Shift Combined'!K65 -> Not Running | AM56: ='(1st+2nd) Shift Combined'!K66 -> Not Running | AR56: ='(1st+2nd) Shift Combined'!K67 -> Not Running | AW56: ='(1st+2nd) Shift Combined'!K68 -> Not Running | BB56: ='(1st+2nd) Shift Combined'!K69 -> Not Running
D59: ='(1st+2nd) Shift Combined'!G65 | I59: ='(1st+2nd) Shift Combined'!G66 | N59: ='(1st+2nd) Shift Combined'!G67 | S59: ='(1st+2nd) Shift Combined'!G68 | X59: ='(1st+2nd) Shift Combined'!G69 | AI59: ='(1st+2nd) Shift Combined'!N65 | AN59: ='(1st+2nd) Shift Combined'!N66 | AS59: ='(1st+2nd) Shift Combined'!N67 | AX59: ='(1st+2nd) Shift Combined'!N68 | BC59: ='(1st+2nd) Shift Combined'!N69
D61: M/C No-41 | I61: M/C No-42 | N61: M/C No-43 | S61: M/C No-44 | X61: M/C No-45 | AI61: M/C No-141 | AN61: M/C No-142 | AS61: M/C No-143 | AX61: M/C No-144 | BC61: M/C No-145
C62: ='(1st+2nd) Shift Combined'!D70 -> Not Running | H62: ='(1st+2nd) Shift Combined'!D71 -> Not Running | M62: ='(1st+2nd) Shift Combined'!D72 -> Not Running | R62: ='(1st+2nd) Shift Combined'!D73 -> Not Running | W62: ='(1st+2nd) Shift Combined'!D74 -> Not Running | AH62: ='(1st+2nd) Shift Combined'!K70 -> Not Running | AM62: ='(1st+2nd) Shift Combined'!K71 -> Not Running | AR62: ='(1st+2nd) Shift Combined'!K72 -> Not Running | AW62: ='(1st+2nd) Shift Combined'!K73 -> Not Running | BB62: ='(1st+2nd) Shift Combined'!K74 -> Not Running
D65: ='(1st+2nd) Shift Combined'!G70 | I65: ='(1st+2nd) Shift Combined'!G71 | N65: ='(1st+2nd) Shift Combined'!G72 | S65: ='(1st+2nd) Shift Combined'!G73 | X65: ='(1st+2nd) Shift Combined'!G74 | AI65: ='(1st+2nd) Shift Combined'!N70 | AN65: ='(1st+2nd) Shift Combined'!N71 | AS65: ='(1st+2nd) Shift Combined'!N72 | AX65: ='(1st+2nd) Shift Combined'!N73 | BC65: ='(1st+2nd) Shift Combined'!N74
D67: M/C No-46 | I67: M/C No-47 | N67: M/C No-48 | S67: M/C No-49 | X67: M/C No-50 | AI67: M/C No-146 | AN67: M/C No-147 | AS67: M/C No-148 | AX67: M/C No-149 | BC67: M/C No-150
C68: ='(1st+2nd) Shift Combined'!D75 -> Not Running | H68: ='(1st+2nd) Shift Combined'!D76 -> Not Running | M68: ='(1st+2nd) Shift Combined'!D77 -> Not Running | R68: ='(1st+2nd) Shift Combined'!D78 -> Not Running | W68: ='(1st+2nd) Shift Combined'!D79 -> Not Running | AH68: ='(1st+2nd) Shift Combined'!K75 -> Not Running | AM68: ='(1st+2nd) Shift Combined'!K76 -> Not Running | AR68: ='(1st+2nd) Shift Combined'!K77 -> Not Running | AW68: ='(1st+2nd) Shift Combined'!K78 -> Not Running | BB68: ='(1st+2nd) Shift Combined'!K79 -> Not Running
D71: ='(1st+2nd) Shift Combined'!G75 | I71: ='(1st+2nd) Shift Combined'!G76 | N71: ='(1st+2nd) Shift Combined'!G77 | S71: ='(1st+2nd) Shift Combined'!G78 | X71: ='(1st+2nd) Shift Combined'!G79 | AI71: ='(1st+2nd) Shift Combined'!N75 | AN71: ='(1st+2nd) Shift Combined'!N76 | AS71: ='(1st+2nd) Shift Combined'!N77 | AX71: ='(1st+2nd) Shift Combined'!N78 | BC71: ='(1st+2nd) Shift Combined'!N79
D73: M/C No-51 | I73: M/C No-52 | N73: M/C No-53 | S73: M/C No-54 | X73: M/C No-55 | AI73: M/C No-151 | AN73: M/C No-152 | AS73: M/C No-153 | AX73: M/C No-154 | BC73: M/C No-155
C74: ='(1st+2nd) Shift Combined'!D80 -> Not Running | H74: ='(1st+2nd) Shift Combined'!D81 -> Not Running | M74: ='(1st+2nd) Shift Combined'!D82 -> Not Running | R74: ='(1st+2nd) Shift Combined'!D83 -> Not Running | W74: ='(1st+2nd) Shift Combined'!D84 -> Not Running | AH74: ='(1st+2nd) Shift Combined'!K80 -> Not Running | AM74: ='(1st+2nd) Shift Combined'!K81 -> Not Running | AR74: ='(1st+2nd) Shift Combined'!K82 -> Not Running | AW74: ='(1st+2nd) Shift Combined'!K83 -> Not Running | BB74: ='(1st+2nd) Shift Combined'!K84 -> Not Running
D77: ='(1st+2nd) Shift Combined'!G80 | I77: ='(1st+2nd) Shift Combined'!G81 | N77: ='(1st+2nd) Shift Combined'!G82 | S77: ='(1st+2nd) Shift Combined'!G83 | X77: ='(1st+2nd) Shift Combined'!G84 | AI77: ='(1st+2nd) Shift Combined'!N80 | AN77: ='(1st+2nd) Shift Combined'!N81 | AS77: ='(1st+2nd) Shift Combined'!N82 | AX77: ='(1st+2nd) Shift Combined'!N83 | BC77: ='(1st+2nd) Shift Combined'!N84
D79: M/C No-56 | I79: M/C No-57 | N79: M/C No-58 | S79: M/C No-59 | X79: M/C No-60 | AI79: M/C No-156 | AN79: M/C No-157 | AS79: M/C No-158 | AX79: M/C No-159 | BC79: M/C No-60
C80: ='(1st+2nd) Shift Combined'!D85 -> Not Running | H80: ='(1st+2nd) Shift Combined'!D86 -> Not Running | M80: ='(1st+2nd) Shift Combined'!D87 -> Not Running | R80: ='(1st+2nd) Shift Combined'!D88 -> Not Running | W80: ='(1st+2nd) Shift Combined'!D89 -> Not Running | AH80: ='(1st+2nd) Shift Combined'!K85 -> Not Running | AM80: ='(1st+2nd) Shift Combined'!K86 -> Not Running | AR80: ='(1st+2nd) Shift Combined'!K87 -> Not Running | AW80: ='(1st+2nd) Shift Combined'!K88 -> Not Running | BB80: ='(1st+2nd) Shift Combined'!K89 -> Not Running
D83: ='(1st+2nd) Shift Combined'!G85 | I83: ='(1st+2nd) Shift Combined'!G86 | N83: ='(1st+2nd) Shift Combined'!G87 | S83: ='(1st+2nd) Shift Combined'!G88 | X83: ='(1st+2nd) Shift Combined'!G89 | AI83: ='(1st+2nd) Shift Combined'!N85 | AN83: ='(1st+2nd) Shift Combined'!N86 | AS83: ='(1st+2nd) Shift Combined'!N87 | AX83: ='(1st+2nd) Shift Combined'!N88 | BC83: ='(1st+2nd) Shift Combined'!N89
B84: PATH | AG84: PATH
...
